Workbook

Sheet Gantt
A1: Gantt Chart Proyek Shea Daily (Ringkasan per Fase)
A2: Otomatis mengikuti status di sheet WBS. Gelap = progres selesai, terang = sisa. Abu-abu = UTS Mg 11 dan UAS Mg 16, kuning = milestone M1-M9.
A3: ="Posisi saat ini: "&TEXT(TODAY(),"dd-mm-yyyy")&" = Minggu "&(INT((TODAY()-WBS!$E$2)/7)+1) -> Posisi saat ini: 19-10-2026 = Minggu 4
A33: Rencana ini dipantau setiap minggu
A34: Warna: | B34: Manajemen | C34: Definisi | D34: Perencanaan | E34: Analisis | F34: Desain | G34: Pemrograman | H34: Pengujian | I34: Penerapan | J34: UTS / UAS | K34: Milestone
A35: Data bantu grafik (otomatis, jangan diedit)
A36: Item | B36: Mulai (Mg) | C36: Selesai (Mg) | D36: Sisa (Mg) | E36: Minggu | F36: Progres / Status
A37: Manajemen Proyek | B37: =(INT((WBS!E5-WBS!$E$2)/7)+1) -> 1 | C37: =ROUND(F37*((INT((WBS!F5-WBS!$E$2)/7)+1)-B37+1),1) -> 3.1 | D37: =ROUND(((INT((WBS!F5-WBS!$E$2)/7)+1)-B37+1)-C37,1) -> 11.9 | E37: ="Mg "&B37&IF((INT((WBS!F5-WBS!$E$2)/7)+1)>B37,"-"&(INT((WBS!F5-WBS!$E$2)/7)+1),"") -> Mg 1-15 | F37: =WBS!J5 -> 0.20952381
A38: Definisi | B38: =(INT((WBS!E9-WBS!$E$2)/7)+1) -> 1 | C38: =ROUND(F38*((INT((WBS!F9-WBS!$E$2)/7)+1)-B38+1),1) -> 2 | D38: =ROUND(((INT((WBS!F9-WBS!$E$2)/7)+1)-B38+1)-C38,1) -> 1 | E38: ="Mg "&B38&IF((INT((WBS!F9-WBS!$E$2)/7)+1)>B38,"-"&(INT((WBS!F9-WBS!$E$2)/7)+1),"") -> Mg 1-3 | F38: =WBS!J9 -> 0.68181818
A39: Perencanaan | B39: =(INT((WBS!E13-WBS!$E$2)/7)+1) -> 3 | C39: =ROUND(F39*((INT((WBS!F13-WBS!$E$2)/7)+1)-B39+1),1) -> 2 | D39: =ROUND(((INT((WBS!F13-WBS!$E$2)/7)+1)-B39+1)-C39,1) -> 0 | E39: ="Mg "&B39&IF((INT((WBS!F13-WBS!$E$2)/7)+1)>B39,"-"&(INT((WBS!F13-WBS!$E$2)/7)+1),"") -> Mg 3-4 | F39: =WBS!J13 -> 1
A40: Analisis | B40: =(INT((WBS!E18-WBS!$E$2)/7)+1) -> 5 | C40: =ROUND(F40*((INT((WBS!F18-WBS!$E$2)/7)+1)-B40+1),1) -> 0 | D40: =ROUND(((INT((WBS!F18-WBS!$E$2)/7)+1)-B40+1)-C40,1) -> 2 | E40: ="Mg "&B40&IF((INT((WBS!F18-WBS!$E$2)/7)+1)>B40,"-"&(INT((WBS!F18-WBS!$E$2)/7)+1),"") -> Mg 5-6 | F40: =WBS!J18 -> 0
A41: Desain | B41: =(INT((WBS!E23-WBS!$E$2)/7)+1) -> 7 | C41: =ROUND(F41*((INT((WBS!F23-WBS!$E$2)/7)+1)-B41+1),1) -> 0 | D41: =ROUND(((INT((WBS!F23-WBS!$E$2)/7)+1)-B41+1)-C41,1) -> 2 | E41: ="Mg "&B41&IF((INT((WBS!F23-WBS!$E$2)/7)+1)>B41,"-"&(INT((WBS!F23-WBS!$E$2)/7)+1),"") -> Mg 7-8 | F41: =WBS!J23 -> 0
A42: Pemrograman | B42: =(INT((WBS!E28-WBS!$E$2)/7)+1) -> 9 | C42: =ROUND(F42*((INT((WBS!F28-WBS!$E$2)/7)+1)-B42+1),1) -> 0 | D42: =ROUND(((INT((WBS!F28-WBS!$E$2)/7)+1)-B42+1)-C42,1) -> 4 | E42: ="Mg "&B42&IF((INT((WBS!F28-WBS!$E$2)/7)+1)>B42,"-"&(INT((WBS!F28-WBS!$E$2)/7)+1),"") -> Mg 9-12 | F42: =WBS!J28 -> 0
A43: Pengujian | B43: =(INT((WBS!E33-WBS!$E$2)/7)+1) -> 13 | C43: =ROUND(F43*((INT((WBS!F33-WBS!$E$2)/7)+1)-B43+1),1) -> 0 | D43: =ROUND(((INT((WBS!F33-WBS!$E$2)/7)+1)-B43+1)-C43,1) -> 1 | E43: ="Mg "&B43&IF((INT((WBS!F33-WBS!$E$2)/7)+1)>B43,"-"&(INT((WBS!F33-WBS!$E$2)/7)+1),"") -> Mg 13 | F43: =WBS!J33 -> 0
A44: Penerapan | B44: =(INT((WBS!E37-WBS!$E$2)/7)+1) -> 14 | C44: =ROUND(F44*((INT((WBS!F37-WBS!$E$2)/7)+1)-B44+1),1) -> 0 | D44: =ROUND(((INT((WBS!F37-WBS!$E$2)/7)+1)-B44+1)-C44,1) -> 2 | E44: ="Mg "&B44&IF((INT((WBS!F37-WBS!$E$2)/7)+1)>B44,"-"&(INT((WBS!F37-WBS!$E$2)/7)+1),"") -> Mg 14-15 | F44: =WBS!J37 -> 0
A45: UTS (Mg 11) | B45: 11 | C45: 0 | D45: 1 | E45: Mg 11 | F45: Libur/ujian
A46: UAS (Mg 16) | B46: 16 | C46: 0 | D46: 1 | E46: Mg 16 | F46: Libur/ujian
A47: M1 RD disetujui klien | B47: =Milestone!C4+0.35 -> 3.35 | C47: 0 | D47: 0.3 | E47: ="Mg "&Milestone!C4 -> Mg 3 | F47: =Milestone!G4 -> Terlambat
A48: M2 WBS & Gantt selesai | B48: =Milestone!C5+0.35 -> 4.35 | C48: 0 | D48: 0.3 | E48: ="Mg "&Milestone!C5 -> Mg 4 | F48: =Milestone!G5 -> ✓ Tercapai
A49: M3 SRS selesai | B49: =Milestone!C6+0.35 -> 6.35 | C49: 0 | D49: 0.3 | E49: ="Mg "&Milestone!C6 -> Mg 6 | F49: =Milestone!G6 -> Belum
A50: M4 SDD selesai | B50: =Milestone!C7+0.35 -> 8.35 | C50: 0 | D50: 0.3 | E50: ="Mg "&Milestone!C7 -> Mg 8 | F50: =Milestone!G7 -> Belum
A51: M5 Demo Modul 1 | B51: =Milestone!C8+0.35 -> 9.35 | C51: 0 | D51: 0.3 | E51: ="Mg "&Milestone!C8 -> Mg 9 | F51: =Milestone!G8 -> Belum
A52: M6 Demo Modul 2 | B52: =Milestone!C9+0.35 -> 10.35 | C52: 0 | D52: 0.3 | E52: ="Mg "&Milestone!C9 -> Mg 10 | F52: =Milestone!G9 -> Belum
A53: M7 Demo Modul 3 | B53: =Milestone!C10+0.35 -> 12.35 | C53: 0 | D53: 0.3 | E53: ="Mg "&Milestone!C10 -> Mg 12 | F53: =Milestone!G10 -> Belum
A54: M8 UAT diterima | B54: =Milestone!C11+0.35 -> 13.35 | C54: 0 | D54: 0.3 | E54: ="Mg "&Milestone!C11 -> Mg 13 | F54: =Milestone!G11 -> Belum
A55: M9 Pelatihan & BAST | B55: =Milestone!C12+0.35 -> 15.35 | C55: 0 | D55: 0.3 | E55: ="Mg "&Milestone!C12 -> Mg 15 | F55: =Milestone!G12 -> Belum

Sheet WBS
A1: Work Breakdown Structure & Jadwal Proyek Shea Daily
A2: Ubah kolom Status (dropdown) → Gantt otomatis ikut. Tanggal Mg 1: | E2: 46293
A3: ="Hari ini: "&TEXT(TODAY(),"dd-mm-yyyy")&" (Minggu "&(INT((TODAY()-$E$2)/7)+1)&")" -> Hari ini: 19-10-2026 (Minggu 4) | O3: =$E$2+0 -> 46293 | P3: =$E$2+7 -> 46300 | Q3: =$E$2+14 -> 46307 | R3: =$E$2+21 -> 46314 | S3: =$E$2+28 -> 46321 | T3: =$E$2+35 -> 46328 | U3: =$E$2+42 -> 46335 | V3: =$E$2+49 -> 46342 | W3: =$E$2+56 -> 46349 | X3: =$E$2+63 -> 46356 | Y3: =$E$2+70 -> 46363 | Z3: =$E$2+77 -> 46370 | AA3: =$E$2+84 -> 46377 | AB3: =$E$2+91 -> 46384 | AC3: =$E$2+98 -> 46391 | AD3: =$E$2+105 -> 46398
A4: Kode | B4: Paket Kerja | C4: Deliverable | D4: PIC (Peran) | E4: Mulai | F4: Selesai | G4: Durasi (hari) | H4: Pendahulu | I4: Status | J4: Progres | K4: Level | L4: Induk | M4: Hari selesai | O4: Mg 1 | P4: Mg 2 | Q4: Mg 3 | R4: Mg 4 | S4: Mg 5 | T4: Mg 6 | U4: Mg 7 | V4: Mg 8 | W4: Mg 9 | X4: Mg 10 | Y4: Mg 11 UTS | Z4: Mg 12 | AA4: Mg 13 | AB4: Mg 14 | AC4: Mg 15 | AD4: Mg 16 UAS
A5: 1 | B5: Manajemen Proyek | C5: Notulen, laporan status | D5: PM (Rico) | E5: =MIN(E6:E8) -> 46293 | F5: =MAX(F6:F8) -> 46397 | G5: =F5-E5+1 -> 105 | I5: Berjalan | J5: =MAX(0,MIN(1,(TODAY()-E5+1)/G5)) -> 0.20952381 | K5: 1
A6: 1.1 | B6: Rapat mingguan tim & klien | C6: Notulen rapat | D6: PM (Rico) | E6: 46293 | F6: 46397 | G6: =F6-E6+1 -> 105 | I6: Berjalan | J6: =IF(I6="✓ Selesai",1,0) -> 0 | K6: 2 | L6: 1 | M6: =IF(I6="✓ Selesai",G6,0) -> 0
A7: 1.2 | B7: Pemantauan jadwal & risiko | C7: Gantt (kolom realisasi), daftar risiko | D7: PM (Rico) | E7: 46293 | F7: 46397 | G7: =F7-E7+1 -> 105 | I7: Berjalan | J7: =IF(I7="✓ Selesai",1,0) -> 0 | K7: 2 | L7: 1 | M7: =IF(I7="✓ Selesai",G7,0) -> 0
A8: 1.3 | B8: Komunikasi & persetujuan klien | C8: Lembar persetujuan, hasil review | D8: PM (Rico) | E8: 46293 | F8: 46383 | G8: =F8-E8+1 -> 91 | I8: Berjalan | J8: =IF(I8="✓ Selesai",1,0) -> 0 | K8: 2 | L8: 1 | M8: =IF(I8="✓ Selesai",G8,0) -> 0
A9: 2 | B9: Definisi Proyek | C9: Requirement Document | D9: SA (Rifki) | E9: =MIN(E10:E12) -> 46293 | F9: =MAX(F10:F12) -> 46313 | G9: =F9-E9+1 -> 21 | H9: - | I9: =IF(J9>=1,"✓ Selesai",IF(COUNTIFS($L$5:$L$41,2,$I$5:$I$41,"Terlambat")>0,"Terlambat",IF(OR(J9>0,COUNTIFS($L$5:$L$41,2,$I$5:$I$41,"Berjalan")>0),"Berjalan","Belum"))) -> Terlambat | J9: =IFERROR(SUMIFS($M$5:$M$41,$L$5:$L$41,2)/SUMIFS($G$5:$G$41,$L$5:$L$41,2),0) -> 0.68181818 | K9: 1
A10: 2.1 | B10: Identifikasi klien & masalah (wawancara) | C10: Notulen wawancara 10 Okt | D10: SA (Rifki) | E10: 46293 | F10: 46305 | G10: =F10-E10+1 -> 13 | H10: - | I10: ✓ Selesai | J10: =IF(I10="✓ Selesai",1,0) -> 1 | K10: 2 | L10: 2 | M10: =IF(I10="✓ Selesai",G10,0) -> 13
A11: 2.2 | B11: Penyusunan Requirement Document | C11: Requirement Document (Bag. I) | D11: SA (Rifki) | E11: 46306 | F11: 46307 | G11: =F11-E11+1 -> 2 | H11: 2.1 | I11: ✓ Selesai | J11: =IF(I11="✓ Selesai",1,0) -> 1 | K11: 2 | L11: 2 | M11: =IF(I11="✓ Selesai",G11,0) -> 2
A12: 2.3 | B12: Persetujuan klien atas RD | C12: Lembar persetujuan klien | D12: PM (Rico) | E12: 46307 | F12: 46313 | G12: =F12-E12+1 -> 7 | H12: 2.2 | I12: Terlambat | J12: =IF(I12="✓ Selesai",1,0) -> 0 | K12: 2 | L12: 2 | M12: =IF(I12="✓ Selesai",G12,0) -> 0
A13: 3 | B13: Perencanaan | C13: Dokumen 01 Bag. II, Gantt Chart | D13: PM (Rico) | E13: =MIN(E14:E17) -> 46307 | F13: =MAX(F14:F17) -> 46320 | G13: =F13-E13+1 -> 14 | H13: 2 | I13: =IF(J13>=1,"✓ Selesai",IF(COUNTIFS($L$5:$L$41,3,$I$5:$I$41,"Terlambat")>0,"Terlambat",IF(OR(J13>0,COUNTIFS($L$5:$L$41,3,$I$5:$I$41,"Berjalan")>0),"Berjalan","Belum"))) -> ✓ Selesai | J13: =IFERROR(SUMIFS($M$5:$M$41,$L$5:$L$41,3)/SUMIFS($G$5:$G$41,$L$5:$L$41,3),0) -> 1 | K13: 1
A14: 3.1 | B14: Proses bisnis & gambaran sistem | C14: Diagram as-is, to-be, gambaran sistem | D14: SD (Rifqi) | E14: 46307 | F14: 46311 | G14: =F14-E14+1 -> 5 | H14: 2 | I14: ✓ Selesai | J14: =IF(I14="✓ Selesai",1,0) -> 1 | K14: 2 | L14: 3 | M14: =IF(I14="✓ Selesai",G14,0) -> 5
A15: 3.2 | B15: Analisis kelayakan | C15: Analisis teknis, ekonomi, operasional | D15: SA (Rifki) | E15: 46307 | F15: 46312 | G15: =F15-E15+1 -> 6 | H15: 2 | I15: ✓ Selesai | J15: =IF(I15="✓ Selesai",1,0) -> 1 | K15: 2 | L15: 3 | M15: =IF(I15="✓ Selesai",G15,0) -> 6
A16: 3.3 | B16: WBS & Gantt Chart | C16: WBS, Gantt Chart (Excel) | D16: PM (Rico) | E16: 46312 | F16: 46313 | G16: =F16-E16+1 -> 2 | H16: 3.1, 3.2 | I16: ✓ Selesai | J16: =IF(I16="✓ Selesai",1,0) -> 1 | K16: 2 | L16: 3 | M16: =IF(I16="✓ Selesai",G16,0) -> 2
A17: 3.4 | B17: Penyusunan dokumen & presentasi | C17: Dokumen 01 Bag. II, PPT | D17: PM (Rico) | E17: 46314 | F17: 46320 | G17: =F17-E17+1 -> 7 | H17: 3.3 | I17: ✓ Selesai | J17: =IF(I17="✓ Selesai",1,0) -> 1 | K17: 2 | L17: 3 | M17: =IF(I17="✓ Selesai",G17,0) -> 7
A18: 4 | B18: Analisis Kebutuhan | C18: SRS | D18: SA (Rifki) | E18: =MIN(E19:E22) -> 46321 | F18: =MAX(F19:F22) -> 46334 | G18: =F18-E18+1 -> 14 | H18: 3 | I18: =IF(J18>=1,"✓ Selesai",IF(COUNTIFS($L$5:$L$41,4,$I$5:$I$41,"Terlambat")>0,"Terlambat",IF(OR(J18>0,COUNTIFS($L$5:$L$41,4,$I$5:$I$41,"Berjalan")>0),"Berjalan","Belum"))) -> Belum | J18: =IFERROR(SUMIFS($M$5:$M$41,$L$5:$L$41,4)/SUMIFS($G$5:$G$41,$L$5:$L$41,4),0) -> 0 | K18: 1
A19: 4.1 | B19: Wawancara & observasi lanjutan | C19: Catatan kebutuhan rinci | D19: SA (Rifki) | E19: 46321 | F19: 46325 | G19: =F19-E19+1 -> 5 | H19: 3 | I19: Belum | J19: =IF(I19="✓ Selesai",1,0) -> 0 | K19: 2 | L19: 4 | M19: =IF(I19="✓ Selesai",G19,0) -> 0
A20: 4.2 | B20: Spesifikasi kebutuhan fungsional & non-fungsional | C20: Draf SRS | D20: SA (Rifki) | E20: 46326 | F20: 46331 | G20: =F20-E20+1 -> 6 | H20: 4.1 | I20: Belum | J20: =IF(I20="✓ Selesai",1,0) -> 0 | K20: 2 | L20: 4 | M20: =IF(I20="✓ Selesai",G20,0) -> 0
A21: 4.3 | B21: Use case & skenario penggunaan | C21: Use case diagram, skenario | D21: SA (Rifki) | E21: 46329 | F21: 46331 | G21: =F21-E21+1 -> 3 | H21: 4.1 | I21: Belum | J21: =IF(I21="✓ Selesai",1,0) -> 0 | K21: 2 | L21: 4 | M21: =IF(I21="✓ Selesai",G21,0) -> 0
A22: 4.4 | B22: Review SRS & persetujuan klien | C22: SRS final | D22: PM (Rico) | E22: 46332 | F22: 46334 | G22: =F22-E22+1 -> 3 | H22: 4.2, 4.3 | I22: Belum | J22: =IF(I22="✓ Selesai",1,0) -> 0 | K22: 2 | L22: 4 | M22: =IF(I22="✓ Selesai",G22,0) -> 0
A23: 5 | B23: Desain Sistem | C23: SDD, prototipe UI | D23: SD (Rifqi) | E23: =MIN(E24:E27) -> 46335 | F23: =MAX(F24:F27) -> 46348 | G23: =F23-E23+1 -> 14 | H23: 4 | I23: =IF(J23>=1,"✓ Selesai",IF(COUNTIFS($L$5:$L$41,5,$I$5:$I$41,"Terlambat")>0,"Terlambat",IF(OR(J23>0,COUNTIFS($L$5:$L$41,5,$I$5:$I$41,"Berjalan")>0),"Berjalan","Belum"))) -> Belum | J23: =IFERROR(SUMIFS($M$5:$M$41,$L$5:$L$41,5)/SUMIFS($G$5:$G$41,$L$5:$L$41,5),0) -> 0 | K23: 1
A24: 5.1 | B24: Perancangan arsitektur & basis data (ERD) | C24: Arsitektur, ERD | D24: SD (Rifqi) | E24: 46335 | F24: 46339 | G24: =F24-E24+1 -> 5 | H24: 4 | I24: Belum | J24: =IF(I24="✓ Selesai",1,0) -> 0 | K24: 2 | L24: 5 | M24: =IF(I24="✓ Selesai",G24,0) -> 0
A25: 5.2 | B25: Wireframe & prototipe UI | C25: Wireframe, prototipe Figma | D25: SD (Rifqi) | E25: 46337 | F25: 46345 | G25: =F25-E25+1 -> 9 | H25: 4 | I25: Belum | J25: =IF(I25="✓ Selesai",1,0) -> 0 | K25: 2 | L25: 5 | M25: =IF(I25="✓ Selesai",G25,0) -> 0
A26: 5.3 | B26: Spesifikasi integrasi RajaOngkir & Midtrans | C26: Spesifikasi API | D26: Programmer (Ricardo) | E26: 46335 | F26: 46340 | G26: =F26-E26+1 -> 6 | H26: 4 | I26: Belum | J26: =IF(I26="✓ Selesai",1,0) -> 0 | K26: 2 | L26: 5 | M26: =IF(I26="✓ Selesai",G26,0) -> 0
A27: 5.4 | B27: Persetujuan prototipe klien & SDD | C27: SDD final, persetujuan prototipe | D27: PM (Rico) | E27: 46345 | F27: 46348 | G27: =F27-E27+1 -> 4 | H27: 5.1, 5.2, 5.3 | I27: Belum | J27: =IF(I27="✓ Selesai",1,0) -> 0 | K27: 2 | L27: 5 | M27: =IF(I27="✓ Selesai",G27,0) -> 0
A28: 6 | B28: Pemrograman | C28: Aplikasi, dok. implementasi | D28: Programmer (Ricardo) | E28: =MIN(E29:E32) -> 46349 | F28: =MAX(F29:F32) -> 46376 | G28: =F28-E28+1 -> 28 | H28: 5 | I28: =IF(J28>=1,"✓ Selesai",IF(COUNTIFS($L$5:$L$41,6,$I$5:$I$41,"Terlambat")>0,"Terlambat",IF(OR(J28>0,COUNTIFS($L$5:$L$41,6,$I$5:$I$41,"Berjalan")>0),"Berjalan","Belum"))) -> Belum | J28: =IFERROR(SUMIFS($M$5:$M$41,$L$5:$L$41,6)/SUMIFS($G$5:$G$41,$L$5:$L$41,6),0) -> 0 | K28: 1
A29: 6.1 | B29: Modul 1: autentikasi, produk & katalog | C29: Modul berjalan + demo (M5) | D29: Programmer (Ricardo) | E29: 46349 | F29: 46355 | G29: =F29-E29+1 -> 7 | H29: 5 | I29: Belum | J29: =IF(I29="✓ Selesai",1,0) -> 0 | K29: 2 | L29: 6 | M29: =IF(I29="✓ Selesai",G29,0) -> 0
A30: 6.2 | B30: Modul 2: keranjang, checkout, ongkir, pembayaran | C30: Modul berjalan + demo (M6) | D30: Programmer (Ricardo) | E30: 46356 | F30: 46362 | G30: =F30-E30+1 -> 7 | H30: 6.1 | I30: Belum | J30: =IF(I30="✓ Selesai",1,0) -> 0 | K30: 2 | L30: 6 | M30: =IF(I30="✓ Selesai",G30,0) -> 0
A31: 6.3 | B31: Modul 3: admin (produk, stok, pesanan), ulasan, halaman info | C31: Aplikasi lengkap + demo (M7) | D31: Programmer (Ricardo) | E31: 46370 | F31: 46376 | G31: =F31-E31+1 -> 7 | H31: 6.2 | I31: Belum | J31: =IF(I31="✓ Selesai",1,0) -> 0 | K31: 2 | L31: 6 | M31: =IF(I31="✓ Selesai",G31,0) -> 0
A32: 6.4 | B32: Dokumen implementasi | C32: Dokumen implementasi | D32: Programmer (Ricardo) | E32: 46373 | F32: 46376 | G32: =F32-E32+1 -> 4 | H32: 6.2 | I32: Belum | J32: =IF(I32="✓ Selesai",1,0) -> 0 | K32: 2 | L32: 6 | M32: =IF(I32="✓ Selesai",G32,0) -> 0
A33: 7 | B33: Pengujian | C33: Skenario uji & UAT | D33: Tester (Rifki) | E33: =MIN(E34:E36) -> 46377 | F33: =MAX(F34:F36) -> 46383 | G33: =F33-E33+1 -> 7 | H33: 6 | I33: =IF(J33>=1,"✓ Selesai",IF(COUNTIFS($L$5:$L$41,7,$I$5:$I$41,"Terlambat")>0,"Terlambat",IF(OR(J33>0,COUNTIFS($L$5:$L$41,7,$I$5:$I$41,"Berjalan")>0),"Berjalan","Belum"))) -> Belum | J33: =IFERROR(SUMIFS($M$5:$M$41,$L$5:$L$41,7)/SUMIFS($G$5:$G$41,$L$5:$L$41,7),0) -> 0 | K33: 1
A34: 7.1 | B34: Pengujian modul & integrasi | C34: Hasil uji modul & integrasi | D34: Tester (Rifki) | E34: 46377 | F34: 46380 | G34: =F34-E34+1 -> 4 | H34: 6 | I34: Belum | J34: =IF(I34="✓ Selesai",1,0) -> 0 | K34: 2 | L34: 7 | M34: =IF(I34="✓ Selesai",G34,0) -> 0
A35: 7.2 | B35: UAT bersama klien | C35: Hasil UAT | D35: Tester (Rifki) | E35: 46381 | F35: 46383 | G35: =F35-E35+1 -> 3 | H35: 7.1 | I35: Belum | J35: =IF(I35="✓ Selesai",1,0) -> 0 | K35: 2 | L35: 7 | M35: =IF(I35="✓ Selesai",G35,0) -> 0
A36: 7.3 | B36: Perbaikan bug | C36: Catatan perbaikan | D36: Programmer (Ricardo) | E36: 46380 | F36: 46383 | G36: =F36-E36+1 -> 4 | H36: 7.1 | I36: Belum | J36: =IF(I36="✓ Selesai",1,0) -> 0 | K36: 2 | L36: 7 | M36: =IF(I36="✓ Selesai",G36,0) -> 0
A37: 8 | B37: Penerapan | C37: User manual, BAST, laporan | D37: Tech Writer (Rifqi) | E37: =MIN(E38:E41) -> 46384 | F37: =MAX(F38:F41) -> 46397 | G37: =F37-E37+1 -> 14 | H37: 7 | I37: =IF(J37>=1,"✓ Selesai",IF(COUNTIFS($L$5:$L$41,8,$I$5:$I$41,"Terlambat")>0,"Terlambat",IF(OR(J37>0,COUNTIFS($L$5:$L$41,8,$I$5:$I$41,"Berjalan")>0),"Berjalan","Belum"))) -> Belum | J37: =IFERROR(SUMIFS($M$5:$M$41,$L$5:$L$41,8)/SUMIFS($G$5:$G$41,$L$5:$L$41,8),0) -> 0 | K37: 1
A38: 8.1 | B38: Deploy final & konfigurasi domain/hosting | C38: Website live | D38: Programmer (Ricardo) | E38: 46384 | F38: 46388 | G38: =F38-E38+1 -> 5 | H38: 7 | I38: Belum | J38: =IF(I38="✓ Selesai",1,0) -> 0 | K38: 2 | L38: 8 | M38: =IF(I38="✓ Selesai",G38,0) -> 0
A39: 8.2 | B39: Penyusunan user manual | C39: User manual | D39: Tech Writer (Rifqi) | E39: 46384 | F39: 46390 | G39: =F39-E39+1 -> 7 | H39: 7 | I39: Belum | J39: =IF(I39="✓ Selesai",1,0) -> 0 | K39: 2 | L39: 8 | M39: =IF(I39="✓ Selesai",G39,0) -> 0
A40: 8.3 | B40: Pelatihan pengguna | C40: Pelatihan 2 sesi | D40: PM (Rico) | E40: 46391 | F40: 46394 | G40: =F40-E40+1 -> 4 | H40: 8.1, 8.2 | I40: Belum | J40: =IF(I40="✓ Selesai",1,0) -> 0 | K40: 2 | L40: 8 | M40: =IF(I40="✓ Selesai",G40,0) -> 0
...

Sheet Diagram WBS
A1: Diagram WBS Shea Daily: 8 paket level 1 dan 29 paket kerja level 2
A2: Kotak hijau = paket kerja berstatus Selesai di sheet WBS. Minggu pada kotak fase mengikuti tanggal di sheet WBS.
A4: Website E-Commerce Shea Daily | C4: ="1. Manajemen Proyek"&CHAR(10)&"Sepanjang proyek" -> 1. Manajemen Proyek Sepanjang proyek | D4: ├─ | E4: 1.1 Rapat mingguan tim & klien | F4: =WBS!I6 -> Berjalan
B5: ┌─ | D5: ├─ | E5: 1.2 Pemantauan jadwal & risiko | F5: =WBS!I7 -> Berjalan
B6: │ | D6: └─ | E6: 1.3 Komunikasi & persetujuan klien | F6: =WBS!I8 -> Berjalan
B7: │
B8: │ | C8: ="2. Definisi Proyek"&CHAR(10)&"Minggu "&(INT((WBS!E9-WBS!$E$2)/7)+1)&"-"&(INT((WBS!F9-WBS!$E$2)/7)+1) -> 2. Definisi Proyek Minggu 1-3 | D8: ├─ | E8: 2.1 Identifikasi klien & masalah (wawancara) | F8: =WBS!I10 -> ✓ Selesai
B9: ├─ | D9: ├─ | E9: 2.2 Penyusunan Requirement Document | F9: =WBS!I11 -> ✓ Selesai
B10: │ | D10: └─ | E10: 2.3 Persetujuan klien atas RD | F10: =WBS!I12 -> Terlambat
B11: │
B12: │ | C12: ="3. Perencanaan"&CHAR(10)&"Minggu "&(INT((WBS!E13-WBS!$E$2)/7)+1)&"-"&(INT((WBS!F13-WBS!$E$2)/7)+1) -> 3. Perencanaan Minggu 3-4 | D12: ├─ | E12: 3.1 Proses bisnis & gambaran sistem | F12: =WBS!I14 -> ✓ Selesai
B13: ├─ | D13: ├─ | E13: 3.2 Analisis kelayakan | F13: =WBS!I15 -> ✓ Selesai
B14: │ | D14: ├─ | E14: 3.3 WBS & Gantt Chart | F14: =WBS!I16 -> ✓ Selesai
B15: │ | D15: └─ | E15: 3.4 Penyusunan dokumen & presentasi | F15: =WBS!I17 -> ✓ Selesai
B16: │
B17: │ | C17: ="4. Analisis Kebutuhan"&CHAR(10)&"Minggu "&(INT((WBS!E18-WBS!$E$2)/7)+1)&"-"&(INT((WBS!F18-WBS!$E$2)/7)+1) -> 4. Analisis Kebutuhan Minggu 5-6 | D17: ├─ | E17: 4.1 Wawancara & observasi lanjutan | F17: =WBS!I19 -> Belum
B18: ├─ | D18: ├─ | E18: 4.2 Spesifikasi kebutuhan fungsional & non-fungsional | F18: =WBS!I20 -> Belum
B19: │ | D19: ├─ | E19: 4.3 Use case & skenario penggunaan | F19: =WBS!I21 -> Belum
B20: │ | D20: └─ | E20: 4.4 Review SRS & persetujuan klien | F20: =WBS!I22 -> Belum
B21: │
B22: │ | C22: ="5. Desain Sistem"&CHAR(10)&"Minggu "&(INT((WBS!E23-WBS!$E$2)/7)+1)&"-"&(INT((WBS!F23-WBS!$E$2)/7)+1) -> 5. Desain Sistem Minggu 7-8 | D22: ├─ | E22: 5.1 Perancangan arsitektur & basis data (ERD) | F22: =WBS!I24 -> Belum
B23: ├─ | D23: ├─ | E23: 5.2 Wireframe & prototipe UI | F23: =WBS!I25 -> Belum
B24: │ | D24: ├─ | E24: 5.3 Spesifikasi integrasi RajaOngkir & Midtrans | F24: =WBS!I26 -> Belum
B25: │ | D25: └─ | E25: 5.4 Persetujuan prototipe klien & SDD | F25: =WBS!I27 -> Belum
B26: │
B27: │ | C27: ="6. Pemrograman"&CHAR(10)&"Minggu "&(INT((WBS!E28-WBS!$E$2)/7)+1)&"-"&(INT((WBS!F28-WBS!$E$2)/7)+1) -> 6. Pemrograman Minggu 9-12 | D27: ├─ | E27: 6.1 Modul 1: autentikasi, produk & katalog | F27: =WBS!I29 -> Belum
B28: ├─ | D28: ├─ | E28: 6.2 Modul 2: keranjang, checkout, ongkir, pembayaran | F28: =WBS!I30 -> Belum
B29: │ | D29: ├─ | E29: 6.3 Modul 3: admin (produk, stok, pesanan), ulasan, halaman info | F29: =WBS!I31 -> Belum
B30: │ | D30: └─ | E30: 6.4 Dokumen implementasi | F30: =WBS!I32 -> Belum
B31: │
B32: │ | C32: ="7. Pengujian"&CHAR(10)&"Minggu "&(INT((WBS!E33-WBS!$E$2)/7)+1)&"-"&(INT((WBS!F33-WBS!$E$2)/7)+1) -> 7. Pengujian Minggu 13-13 | D32: ├─ | E32: 7.1 Pengujian modul & integrasi | F32: =WBS!I34 -> Belum
B33: ├─ | D33: ├─ | E33: 7.2 UAT bersama klien | F33: =WBS!I35 -> Belum
B34: │ | D34: └─ | E34: 7.3 Perbaikan bug | F34: =WBS!I36 -> Belum
B35: │
B36: │ | C36: ="8. Penerapan"&CHAR(10)&"Minggu "&(INT((WBS!E37-WBS!$E$2)/7)+1)&"-"&(INT((WBS!F37-WBS!$E$2)/7)+1) -> 8. Penerapan Minggu 14-15 | D36: ├─ | E36: 8.1 Deploy final & konfigurasi domain/hosting | F36: =WBS!I38 -> Belum
B37: └─ | D37: ├─ | E37: 8.2 Penyusunan user manual | F37: =WBS!I39 -> Belum
D38: ├─ | E38: 8.3 Pelatihan pengguna | F38: =WBS!I40 -> Belum
D39: └─ | E39: 8.4 BAST & laporan akhir | F39: =WBS!I41 -> Belum

Sheet Milestone
A1: Milestone Proyek Shea Daily
A2: Status otomatis mengikuti status paket kerja terkait di sheet WBS (kolom Paket terkait).
A3: Kode | B3: Milestone | C3: Minggu | D3: Awal minggu | E3: Bukti tercapai | F3: Paket terkait | G3: Status
A4: M1 | B4: Requirement Document disetujui klien | C4: 3 | D4: =WBS!$E$2+7*(C4-1) -> 46307 | E4: Lembar persetujuan klien | F4: 2.3 | G4: =IF(WBS!I12="✓ Selesai","✓ Tercapai",IF(WBS!I12="Terlambat","Terlambat",IF(WBS!I12="Berjalan","Berjalan","Belum"))) -> Terlambat
A5: M2 | B5: Rencana proyek (WBS & Gantt) selesai | C5: 4 | D5: =WBS!$E$2+7*(C5-1) -> 46314 | E5: Dokumen 01 Bagian II | F5: 3 | G5: =IF(WBS!I13="✓ Selesai","✓ Tercapai",IF(WBS!I13="Terlambat","Terlambat",IF(WBS!I13="Berjalan","Berjalan","Belum"))) -> ✓ Tercapai
A6: M3 | B6: SRS selesai | C6: 6 | D6: =WBS!$E$2+7*(C6-1) -> 46328 | E6: Dokumen SRS | F6: 4.4 | G6: =IF(WBS!I22="✓ Selesai","✓ Tercapai",IF(WBS!I22="Terlambat","Terlambat",IF(WBS!I22="Berjalan","Berjalan","Belum"))) -> Belum
A7: M4 | B7: SDD selesai | C7: 8 | D7: =WBS!$E$2+7*(C7-1) -> 46342 | E7: Dokumen SDD | F7: 5.4 | G7: =IF(WBS!I27="✓ Selesai","✓ Tercapai",IF(WBS!I27="Terlambat","Terlambat",IF(WBS!I27="Berjalan","Berjalan","Belum"))) -> Belum
A8: M5 | B8: Demo Modul 1 | C8: 9 | D8: =WBS!$E$2+7*(C8-1) -> 46349 | E8: Demo di kelas | F8: 6.1 | G8: =IF(WBS!I29="✓ Selesai","✓ Tercapai",IF(WBS!I29="Terlambat","Terlambat",IF(WBS!I29="Berjalan","Berjalan","Belum"))) -> Belum
A9: M6 | B9: Demo Modul 2 | C9: 10 | D9: =WBS!$E$2+7*(C9-1) -> 46356 | E9: Demo di kelas | F9: 6.2 | G9: =IF(WBS!I30="✓ Selesai","✓ Tercapai",IF(WBS!I30="Terlambat","Terlambat",IF(WBS!I30="Berjalan","Berjalan","Belum"))) -> Belum
A10: M7 | B10: Demo Modul 3: semua fitur lengkap | C10: 12 | D10: =WBS!$E$2+7*(C10-1) -> 46370 | E10: Aplikasi + dok. implementasi | F10: 6.3 | G10: =IF(WBS!I31="✓ Selesai","✓ Tercapai",IF(WBS!I31="Terlambat","Terlambat",IF(WBS!I31="Berjalan","Berjalan","Belum"))) -> Belum
A11: M8 | B11: UAT diterima klien | C11: 13 | D11: =WBS!$E$2+7*(C11-1) -> 46377 | E11: Hasil UAT | F11: 7.2 | G11: =IF(WBS!I35="✓ Selesai","✓ Tercapai",IF(WBS!I35="Terlambat","Terlambat",IF(WBS!I35="Berjalan","Berjalan","Belum"))) -> Belum
A12: M9 | B12: Pelatihan & BAST | C12: 15 | D12: =WBS!$E$2+7*(C12-1) -> 46391 | E12: BAST bertanda tangan | F12: 8.4 | G12: =IF(WBS!I41="✓ Selesai","✓ Tercapai",IF(WBS!I41="Terlambat","Terlambat",IF(WBS!I41="Berjalan","Berjalan","Belum"))) -> Belum
